# Issue 131: Fix failing test tests/unit/interface/test_api_advanced.py::test_edge_cases_succeeds

Milestone: 0.1.0-alpha.1 (completed 2025-08-16)

## Progress
- Test passes after re-running `pytest`.
- Status: closed

## References
- [tests/unit/interface/test_api_advanced.py](../../tests/unit/interface/test_api_advanced.py)
