
============================================================ ERRORS ============================================================
_______________________________ ERROR collecting tests/behavior/test_agent_api_health_metrics.py _______________________________
.venv/lib/python3.12/site-packages/_pytest/python.py:498: in importtestmodule
    mod = import_path(
.venv/lib/python3.12/site-packages/_pytest/pathlib.py:587: in import_path
    importlib.import_module(module_name)
/root/.pyenv/versions/3.12.10/lib/python3.12/importlib/__init__.py:90: in import_module
    return _bootstrap._gcd_import(name[level:], package, level)
           ^^^^^^^^^^^^^^^^^^^^^^^^^^^^^^^^^^^^^^^^^^^^^^^^^^^^
<frozen importlib._bootstrap>:1387: in _gcd_import
    ???
<frozen importlib._bootstrap>:1360: in _find_and_load
    ???
<frozen importlib._bootstrap>:1331: in _find_and_load_unlocked
    ???
<frozen importlib._bootstrap>:935: in _load_unlocked
    ???
.venv/lib/python3.12/site-packages/_pytest/assertion/rewrite.py:186: in exec_module
    exec(co, module.__dict__)
tests/behavior/test_agent_api_health_metrics.py:8: in <module>
    from .steps.test_agent_api_health_metrics_steps import *  # noqa: F401,F403
    ^^^^^^^^^^^^^^^^^^^^^^^^^^^^^^^^^^^^^^^^^^^^^^^^^^^^^^^^
<frozen importlib._bootstrap>:1360: in _find_and_load
    ???
<frozen importlib._bootstrap>:1331: in _find_and_load_unlocked
    ???
<frozen importlib._bootstrap>:935: in _load_unlocked
    ???
.venv/lib/python3.12/site-packages/_pytest/assertion/rewrite.py:177: in exec_module
    source_stat, co = _rewrite_test(fn, self.config)
                      ^^^^^^^^^^^^^^^^^^^^^^^^^^^^^^
.venv/lib/python3.12/site-packages/_pytest/assertion/rewrite.py:357: in _rewrite_test
    tree = ast.parse(source, filename=strfn)
           ^^^^^^^^^^^^^^^^^^^^^^^^^^^^^^^^^
/root/.pyenv/versions/3.12.10/lib/python3.12/ast.py:52: in parse
    return compile(source, filename, mode, flags,
E     File "/workspace/devsynth/tests/behavior/steps/test_agent_api_health_metrics_steps.py", line 26
E       settings_stub = MagicMock()
E   IndentationError: unexpected indent
======================================================= warnings summary =======================================================
.venv/lib/python3.12/site-packages/pydantic_core/core_schema.py:4137
.venv/lib/python3.12/site-packages/pydantic_core/core_schema.py:4137
  /workspace/devsynth/.venv/lib/python3.12/site-packages/pydantic_core/core_schema.py:4137: DeprecationWarning: `FieldValidationInfo` is deprecated, use `ValidationInfo` instead.
    warnings.warn(msg, DeprecationWarning, stacklevel=1)

-- Docs: https://docs.pytest.org/en/stable/how-to/capture-warnings.html
================================================= Test Categorization Summary ==================================================
Test Type Distribution:
  Unit Tests: 0
  Integration Tests: 0
  Behavior Tests: 0

Test Speed Distribution:
  Fast Tests (< 1s): 0
  Medium Tests (1-5s): 0
  Slow Tests (> 5s): 0
=================================================== short test summary info ====================================================
ERROR tests/behavior/test_agent_api_health_metrics.py
!!!!!!!!!!!!!!!!!!!!!!!!!!!!!!!!!!!!!!!!!!!! Interrupted: 1 error during collection !!!!!!!!!!!!!!!!!!!!!!!!!!!!!!!!!!!!!!!!!!!!
no tests collected, 1 error in 0.34s
